<?xml version="1.0"?>

<robot 
	xmlns:xacro="http://www.ros.org/wiki/xacro" 
    xmlns:sensor="http://playerstage.sourceforge.net/gazebo/xmlschema/#sensor"
    xmlns:controller="http://playerstage.sourceforge.net/gazebo/xmlschema/#controller"
    xmlns:interface="http://playerstage.sourceforge.net/gazebo/xmlschema/#interface"
    name="Person2">

	<xacro:property name="M_PI" value="3.1415926535897931"/>

    <!-- Links and joints definitions -->    
    <!-- HIPS -->
    <link name="Hips_link" />

    <joint name="LHipJoint_joint" type="continuous">
        <parent link="Hips_link" />
        <child link="LHipJoint_link" />
        <origin xyz="0 0 0" rpy="0 0 0" />
    </joint>

    <link name="LHipJoint_link" />


    <joint name="RHipJoint_joint" type="continuous">
        <parent link="Hips_link" />
        <child link="RHipJoint_link" />
        <origin xyz="0 0 0" rpy="0 0 0" />
    </joint>

    <link name="RHipJoint_link" />


	<!-- LEGS -->
	<!-- Up Legs -->
    <joint name="LeftUpLeg_joint" type="continuous">
        <parent link="LHipJoint_link" />
        <child link="LeftUpLeg_link" />
        <origin xyz="1.37733 -1.58235 0.71371" rpy="0 0 0" />
    </joint>

    <link name="LeftUpLeg_link" />


    <joint name="RightUpLeg_joint" type="continuous">
        <parent link="RHipJoint_link" />
        <child link="RightUpLeg_link" />
        <origin xyz="-1.47839 -1.58235 0.71371" rpy="0 0 0" />
    </joint>

    <link name="RightUpLeg_link" />


	<!-- Legs -->
    <joint name="LeftLeg_joint" type="continuous">
        <parent link="LeftUpLeg_link" />
        <child link="LeftLeg_link" />
        <origin xyz="2.33951 -6.42775 0" rpy="0 0 0" />
    </joint>

    <link name="LeftLeg_link" />


    <joint name="RightLeg_joint" type="continuous">
        <parent link="RightUpLeg_link" />
        <child link="RightLeg_link" />
        <origin xyz="-2.26534 -6.22397 0" rpy="0 0 0" />
    </joint>

    <link name="RightLeg_link" />


	<!-- Foot -->
    <joint name="LeftFoot_joint" type="continuous">
        <parent link="LeftLeg_link" />
        <child link="LeftFoot_link" />
        <origin xyz="2.30523 -6.33358 0" rpy="0 0 0" />
    </joint>

    <link name="LeftFoot_link" />


    <joint name="RightFoot_joint" type="continuous">
        <parent link="RightLeg_link" />
        <child link="RightFoot_link" />
        <origin xyz="-2.27037 -6.23779 0" rpy="0 0 0" />
    </joint>

    <link name="RightFoot_link" />


	<!-- Toe Base -->
    <joint name="LeftToeBase_joint" type="continuous">
        <parent link="LeftFoot_link" />
        <child link="LeftToeBase_link" />
        <origin xyz="0.05388 -0.14857 1.63863" rpy="0 0 0" />
    </joint>

    <link name="LeftToeBase_link" />


    <joint name="RightToeBase_joint" type="continuous">
        <parent link="RightFoot_link" />
        <child link="RightToeBase_link" />
        <origin xyz="-0.09543 -0.26220 1.62615" rpy="0 0 0" />
    </joint>

    <link name="RightToeBase_link" />


    <!-- TORSO -->
	<!-- Spine -->
    <joint name="LowerBack_joint" type="continuous">
        <parent link="Hips_link" />
        <child link="LowerBack_link" />
        <origin xyz="0 0 0" rpy="0 0 0" />
    </joint>

    <link name="LowerBack_link" />


    <joint name="Spine_joint" type="continuous">
        <parent link="LowerBack_link" />
        <child link="Spine_link" />
        <origin xyz="0.00101 1.81877 -0.00412" rpy="0 0 0" />
    </joint>

    <link name="Spine_link" />


    <joint name="Spine1_joint" type="continuous">
        <parent link="Spine_link" />
        <child link="Spine1_link" />
        <origin xyz="0.00322 1.81934 -0.03962" rpy="0 0 0" />
    </joint>

    <link name="Spine1_link" />


	<!-- Head -->
    <joint name="Neck_joint" type="continuous">
        <parent link="Spine1_link" />
        <child link="Neck_link" />
        <origin xyz="0 0 0" rpy="0 0 ${-16*M_PI/180}" />
    </joint>

    <link name="Neck_link" />


    <joint name="Neck1_joint" type="continuous">
        <parent link="Neck_link" />
        <child link="Neck1_link" />
        <origin xyz="-0.13795 1.66192 0.22650" rpy="0 0 0" />
    </joint>

    <link name="Neck1_link" />


    <joint name="Head_joint" type="continuous">
        <parent link="Neck1_link" />
        <child link="Head_link" />
        <origin xyz="0.14844 1.65995 -0.39123" rpy="0 0 0" />
    </joint>

    <link name="Head_link" />


	<!-- ARMS -->
	<!-- Shoulders -->
    <joint name="LeftShoulder_joint" type="continuous">
        <parent link="Spine1_link" />
        <child link="LeftShoulder_link" />
        <origin xyz="0 0 0" rpy="0 0 0" />
    </joint>

    <link name="LeftShoulder_link" />


    <joint name="RightShoulder_joint" type="continuous">
        <parent link="Spine1_link" />
        <child link="RightShoulder_link" />
        <origin xyz="0 0 0" rpy="0 0 0" />
    </joint>

    <link name="RightShoulder_link" />


	<!-- Arms -->
    <joint name="LeftArm_joint" type="continuous">
        <parent link="LeftShoulder_link" />
        <child link="LeftArm_link" />
        <origin xyz="3.25446 1.41983 0.32106" rpy="0 0 0" />
    </joint>

    <link name="LeftArm_link" />


    <joint name="RightArm_joint" type="continuous">
        <parent link="RightShoulder_link" />
        <child link="RightArm_link" />
        <origin xyz="-3.30007 1.25485 0.33947" rpy="0 0 0" />
    </joint>

    <link name="RightArm_link" />


	<!-- Fore Arms -->
    <joint name="LeftForeArm_joint" type="continuous">
        <parent link="LeftArm_link" />
        <child link="LeftForeArm_link" />
        <origin xyz="4.05444 0 0" rpy="0 0 0" />
    </joint>

    <link name="LeftForeArm_link" />


    <joint name="RightForeArm_joint" type="continuous">
        <parent link="RightArm_link" />
        <child link="RightForeArm_link" />
        <origin xyz="-3.74048 0 0" rpy="0 0 0" />
    </joint>

    <link name="RightForeArm_link" /> 


	<!-- Hands -->
    <joint name="LeftHand_joint" type="continuous">
        <parent link="LeftForeArm_link" />
        <child link="LeftHand_link" />
        <origin xyz="3.21205 0 0" rpy="0 0 0" />
    </joint>

    <link name="LeftHand_link" /> 


    <joint name="RightHand_joint" type="continuous">
        <parent link="RightForeArm_link" />
        <child link="RightHand_link" />
        <origin xyz="-3.16030 0 0" rpy="0 0 0" />
    </joint>

    <link name="RightHand_link" />


	<!-- Finger Base -->
    <joint name="LeftFingerBase_joint" type="continuous">
        <parent link="LeftHand_link" />
        <child link="LeftFingerBase_link" />
        <origin xyz="0 0 0" rpy="0 0 0" />
    </joint>

    <link name="LeftFingerBase_link" />


    <joint name="RightFingerBase_joint" type="continuous">
        <parent link="RightHand_link" />
        <child link="RightFingerBase_link" />
        <origin xyz="0 0 0" rpy="0 0 0" />
    </joint>

    <link name="RightFingerBase_link" />


	<!-- Hand Index -->
    <joint name="LeftHandIndex1_joint" type="continuous">
        <parent link="LeftHand_link" />
        <child link="LeftHandIndex1_link" />
        <origin xyz="0.70741 0 0" rpy="0 0 0" />
    </joint>

    <link name="LeftHandIndex1_link" />


    <joint name="RightHandIndex1_joint" type="continuous">
        <parent link="RightHand_link" />
        <child link="RightHandIndex1_link" />
        <origin xyz="-0.71703 0 0" rpy="0 0 0" />
    </joint>

    <link name="RightHandIndex1_link" />


	<!-- Thumbs -->
    <joint name="LThumb_joint" type="continuous">
        <parent link="LeftHand_link" />
        <child link="LThumb_link" />
        <origin xyz="0 0 0" rpy="0 0 0" />
    </joint>

    <link name="LThumb_link" />


    <joint name="RThumb_joint" type="continuous">
        <parent link="RightHand_link" />
        <child link="RThumb_link" />
        <origin xyz="0 0 0" rpy="0 0 0" />
    </joint>

    <link name="RThumb_link" />


</robot>
